{
 "cells": [
  {
   "cell_type": "markdown",
   "metadata": {},
   "source": [
    "# <font color='blue'>Data Science Academy - Python Fundamentos - Capítulo 12</font>\n",
    "\n",
    "## Download: http://github.com/dsacademybr"
   ]
  },
  {
   "cell_type": "code",
   "execution_count": null,
   "metadata": {},
   "outputs": [],
   "source": [
    "# Versão da Linguagem Python\n",
    "from platform import python_version\n",
    "print('Versão da Linguagem Python Usada Neste Jupyter Notebook:', python_version())"
   ]
  },
  {
   "cell_type": "markdown",
   "metadata": {},
   "source": [
    "## Detecção de Emoções em Imagens com Inteligência Artificial"
   ]
  },
  {
   "cell_type": "markdown",
   "metadata": {},
   "source": [
    "https://www.kaggle.com/c/facial-keypoints-detector"
   ]
  },
  {
   "cell_type": "markdown",
   "metadata": {},
   "source": [
    "## Redes Neurais Convolucionais"
   ]
  },
  {
   "cell_type": "markdown",
   "metadata": {},
   "source": [
    "Em redes neurais convolucionais, os dados de entrada são muitas vezes moldados como uma matriz 3D (número de canais, largura da imagem, altura), que preserva a relação espacial entre os pixels. Na figura abaixo, a imagem 3 é um único canal (tons de cinza) de dados, portanto, a dimensão de entrada é especificada como uma tupla (1, largura da imagem, altura da imagem)."
   ]
  },
  {
   "cell_type": "markdown",
   "metadata": {},
   "source": [
    "![MNIST-flat](https://www.cntk.ai/jup/cntk103a_MNIST_input.png)"
   ]
  },
  {
   "cell_type": "markdown",
   "metadata": {},
   "source": [
    "Imagens de cor de cena natural são frequentemente apresentadas como canais de cor Vermelho-Verde-Azul (RGB). A dimensão de entrada dessas imagens é especificada como uma tupla (3, largura da imagem, altura da imagem). Se houver dados de entrada RGB como uma varredura volumétrica com largura de volume, altura de volume e profundidade de volume representando os 3 eixos, o formato de dados de entrada será especificado por uma tupla de 4 valores (3, largura de volume, altura de volume, profundidade de volume). Desta forma, podemos especificar as imagens de entrada em espaço arbitrário de dimensão superior."
   ]
  },
  {
   "cell_type": "markdown",
   "metadata": {},
   "source": [
    "![input-rgb](https://www.cntk.ai/jup/cntk103d_rgb.png)"
   ]
  },
  {
   "cell_type": "markdown",
   "metadata": {},
   "source": [
    "CNN é uma rede feedforward composta de diversas camadas de tal forma que a saída de uma camada torna-se a entrada para a próxima camada (semelhante ao MLP). Em MLP, todos os pares possíveis de pixels de entrada são conectados aos nós de saída com cada par tendo um peso, conduzindo assim a uma explosão combinatória de parâmetros a serem aprendidos e também aumentando a possibilidade de overfitting. As camadas de convolução aproveitam a disposição espacial dos pixels e aprendem vários filtros que reduzem significativamente a quantidade de parâmetros na rede. O tamanho do filtro é um parâmetro da camada de convolução.\n",
    "\n",
    "Nesta seção, apresentamos os fundamentos das operações de convolução. \n",
    "\n",
    "### Camada de Convolução\n",
    "\n",
    "Uma camada de convolução é um conjunto de filtros. Cada filtro é definido por uma matriz de peso (** W **) e bias ($ b $).\n",
    "\n",
    "![input-filter](https://www.cntk.ai/jup/cntk103d_filterset.png)\n",
    "\n",
    "Estes filtros são varridos através da imagem que realiza o dot product entre os pesos e o valor de entrada correspondente ($\\vec{x}^T$). O valor de bias é adicionado à saída do dot product e a soma resultante é opcionalmente mapeada através de uma função de ativação. Esse processo é ilustrado na seguinte animação."
   ]
  },
  {
   "cell_type": "code",
   "execution_count": null,
   "metadata": {},
   "outputs": [],
   "source": [
    "from IPython.display import display, Image\n",
    "Image(url=\"https://www.cntk.ai/jup/cntk103d_conv2d_final.gif\", width= 500)"
   ]
  },
  {
   "cell_type": "markdown",
   "metadata": {},
   "source": [
    "As camadas de convolução incorporam as seguintes características-chave:\n",
    "\n",
    "  - Em vez de estar totalmente conectado a todos os pares de nós de entrada e saída, cada nó de convolução é ** conectado localmente ** a um subconjunto de nós de entrada localizados em uma região de entrada menor, também chamada de campo receptivo (RF). A figura acima ilustra pequenas regiões 3 x 3 na imagem como a região RF. No caso de uma imagem RGB, haveria três dessas 3 x 3 regiões, uma de cada um dos 3 canais de cor.\n",
    "   \n",
    "   \n",
    "   - Em vez de ter um único conjunto de pesos (como em uma camada Densa), camadas convolucionais têm vários conjuntos (mostrado na figura com várias cores), chamado ** filtros **. Cada filtro detecta características dentro de cada RF possível na imagem de entrada. A saída da convolução é um conjunto de sub-camadas `n` (mostradas na animação abaixo) onde ` n` é o número de filtros (consulte a figura acima).\n",
    "   \n",
    "     \n",
    "   - Dentro de uma subcamada, em vez de cada nó ter seu próprio conjunto de pesos, um único conjunto de ** pesos compartilhados ** são usados por todos os nós nessa subcamada. Isso reduz o número de parâmetros a serem aprendidos. Isso também abre a porta para vários aspectos da aprendizagem profunda que permitiu a construção de soluções muito práticas:\n",
    "     -- Manuseio de imagens maiores (digamos 512 x 512)\n",
    "     -- Tentando maiores tamanhos de filtro (correspondente a um RF maior) como 11 x 11\n",
    "     -- Aprender mais filtros (digamos 128)\n",
    "     -- Explorar arquiteturas mais profundas (mais de 100 camadas)\n",
    "     -- Alcançar a invariância de tradução (a capacidade de reconhecer um recurso independentemente de onde eles aparecem na imagem)."
   ]
  },
  {
   "cell_type": "markdown",
   "metadata": {},
   "source": [
    "### Strides e Padding\n",
    "\n",
    "** Como os filtros são posicionados? ** Em geral, os filtros são dispostos em telhas sobrepostas, da esquerda para a direita e de cima para baixo. Cada camada de convolução tem um parâmetro para especificar a `filter_shape`, especificando a largura e a altura do filtro no caso das imagens de cena mais naturais. Há um parâmetro (`strides`) que controla a distância até a etapa para a direita ao mover os filtros através de vários RF's em uma linha, e até que ponto para descer quando se move para a próxima linha. O parâmetro booleano `pad` controla se a entrada deve ser preenchida em torno das bordas para permitir um mosaico completo dos RFs perto das bordas.\n",
    "\n",
    "A animação acima mostra os resultados com um `filter_shape` = (3, 3),` strides` = (2, 2) e `pad` = False. As duas animações abaixo mostram os resultados quando `pad` é definido como True. Primeiro, com um passo de 2 e segundo tendo um passo de 1.\n",
    "\n",
    "Nota: a forma da saída é diferente entre as duas configurações. Muitas vezes a sua decisão de pad e os valores de stride é baseada na forma da camada de saída necessária."
   ]
  },
  {
   "cell_type": "code",
   "execution_count": null,
   "metadata": {},
   "outputs": [],
   "source": [
    "from IPython.display import display, Image\n",
    "\n",
    "# Plot images com strides de 2 e 1 e padding habilitado\n",
    "images = [(\"https://www.cntk.ai/jup/cntk103d_padding_strides.gif\" , 'Stride = 2'),\n",
    "          (\"https://www.cntk.ai/jup/cntk103d_same_padding_no_strides.gif\", 'Stride = 1')]\n",
    "\n",
    "for im in images:\n",
    "    print(im[1])\n",
    "    display(Image(url=im[0], width=400, height=400))"
   ]
  },
  {
   "cell_type": "markdown",
   "metadata": {},
   "source": [
    "## Pooling Layer\n",
    "\n",
    "Muitas vezes, é necessário controlar o número de parâmetros, especialmente em redes profundas. Para cada camada de saída da camada de convolução (cada camada, corresponde à saída de um filtro), pode-se ter uma camada de agrupamento (Pooling). As camadas de agrupamento são tipicamente introduzidas para:\n",
    "- Reduzir a dimensionalidade da camada anterior (acelerando a rede),\n",
    "- Torna o modelo mais tolerante a alterações no local do objeto na imagem. Por exemplo, mesmo quando um dígito é deslocado para um lado da imagem em vez de estar no meio.\n",
    "\n",
    "É comum inserir periodicamente uma camada de agrupamento entre as camadas Convolucionais sucessivas em uma arquitetura ConvNet. Sua função é reduzir progressivamente o tamanho espacial da representação para reduzir a quantidade de parâmetros e de computação na rede e, portanto, também para controlar o overfitting. A Camada de Agrupamento opera independentemente em cada fatia de profundidade da entrada e redimensiona-a espacialmente, usando a operação MAX. A forma mais comum é uma camada de pooling com filtros de tamanho 2x2 aplicado com um stride de 2 downsamples cada fatia de profundidade na entrada por 2 ao longo de largura e altura, descartando 75% das ativações. Cada operação MAX, neste caso, seria tomar um máximo de 4 números (pequena região 2x2 em alguma fatia de profundidade). A dimensão da profundidade permanece inalterada.\n",
    "\n",
    "Vale ressaltar que existem apenas duas variações comumente observadas na camada de Max Pooling encontradas na prática: Uma camada de agrupamento com F = 3, S = 2 (também chamada de pool de sobreposição) e mais comumente F = 2, S = 2. Agrupando tamanhos com campos receptivos maiores pode destruir a rede e travar a máquina.\n",
    "\n",
    "O cálculo em um nó de pooling é muito mais simples do que um nó de feedforward normal. Ele não tem peso, bias ou função de ativação. Ele usa uma função de agregação simples (como max ou average) para calcular sua saída. A função mais comumente usada é \"max\" - um nó de pooling máximo simplesmente fornece o máximo dos valores de entrada correspondentes à posição do filtro da entrada. A figura abaixo mostra os valores de entrada em uma região 4 x 4. A tamanho máximo da janela de agrupamento é 2 x 2 e começa a partir do canto superior esquerdo. O valor máximo dentro da janela torna-se a saída da região. Cada vez que o modelo é deslocado pela quantidade especificada pelo parâmetro stride (como mostrado na figura abaixo) e a operação de pooling máximo é repetida.\n",
    "![maxppool](https://cntk.ai/jup/201/MaxPooling.png)"
   ]
  },
  {
   "cell_type": "markdown",
   "metadata": {},
   "source": [
    "# Rede Convolucional Típica\n",
    "\n",
    "![mnist-conv-mp](http://www.cntk.ai/jup/conv103d_mnist-conv-mp.png)\n",
    "\n",
    "Uma CNN típica contém um conjunto de camadas alternadas de convolução e agrupamento (Pooling) seguido por uma camada de saída densa para a classificação. Você encontrará variantes desta estrutura em muitas redes profundas clássicas (VGG, AlexNet, etc.). Isto está em contraste com a rede MLP, que consiste em 2 camadas densas seguidas por uma camada de saída densa.\n",
    "\n",
    "As ilustrações são apresentadas no contexto de imagens bidimensionais (2D), mas o conceito e os componentes podem operar em qualquer dado dimensional. O esquema acima mostra 2 camadas de convolução e 2 camadas de agrupamento máximo. Uma estratégia típica é aumentar o número de filtros nas camadas mais profundas, reduzindo o tamanho espacial de cada camada intermediária. Camadas intermediárias."
   ]
  },
  {
   "cell_type": "markdown",
   "metadata": {},
   "source": [
    "A figura a seguir ilustra o modelo que vamos construir. Observe que os parâmetros no modelo abaixo devem ser experimentados. Estes são frequentemente chamados de hiperparâmetros de rede. Aumentar a forma do filtro leva a um aumento no número de parâmetros do modelo, aumenta o tempo de computação e ajuda o modelo a se ajustar melhor aos dados. No entanto, corre-se o risco de [overfitting](https://en.wikipedia.org/wiki/Overfitting). Normalmente, o número de filtros nas camadas mais profundas é maior do que o número de filtros nas camadas anteriores. Escolhemos 8 e 16 como número de filtros para a primeira e segunda camadas, respectivamente. Estes hiperparâmetros devem ser experimentados durante a construção do modelo.\n",
    "\n",
    "![conv-only](https://www.cntk.ai/jup/cntk103d_convonly2.png)"
   ]
  },
  {
   "cell_type": "markdown",
   "metadata": {},
   "source": [
    "**Compreendendo os parâmetros**:\n",
    "\n",
    "\n",
    "Nosso modelo tem duas camadas de convolução, cada uma com peso e bias. Isso adiciona até 4 tensores de parâmetro. Adicionalmente, a camada densa tem tensores de peso e de bias. Assim, os tensores de 6 parâmetros.\n",
    "\n",
    "Vamos agora contar o número de parâmetros:\n",
    "- * Primeira camada de convolução *: Existem 8 filtros cada um de tamanho (1 x 5 x 5) onde 1 é o número de canais na imagem de entrada. Isto adiciona até 200 valores na matriz de peso e 8 valores de bias.\n",
    "\n",
    "\n",
    "- * Segunda camada de convolução *: Existem 16 filtros cada um de tamanho (8 x 5 x 5) onde 8 é o número de canais na entrada para a segunda camada (= saída da primeira camada). Isto adiciona até 3200 valores na matriz de peso e 16 valores de bias.\n",
    "\n",
    "\n",
    "- * Última camada densa *: Existem 16 x 7 x 7 valores de entrada e produz 10 valores de saída correspondentes aos 10 dígitos no conjunto de dados MNIST. Isto corresponde a (16 x 7 x 7) x 10 valores de peso e 10 valores de bias.\n",
    "\n",
    "Adicionando estes acima dá os 11274 parâmetros no modelo."
   ]
  },
  {
   "cell_type": "markdown",
   "metadata": {},
   "source": [
    "## Construindo e Treinando o Modelo"
   ]
  },
  {
   "cell_type": "markdown",
   "metadata": {},
   "source": [
    "### Definindo os Dados e Hyperparâmetros"
   ]
  },
  {
   "cell_type": "code",
   "execution_count": null,
   "metadata": {},
   "outputs": [],
   "source": [
    "# Versão do TensorFlow\n",
    "# Para instalar a mesma versão do TF, use: \n",
    "# CPU: pip install tensorflow==1.15.2 (no prompt ou terminal)\n",
    "# GPU: pip install tensorflow_gpu==1.15.2 (no prompt ou terminal)"
   ]
  },
  {
   "cell_type": "code",
   "execution_count": null,
   "metadata": {},
   "outputs": [],
   "source": [
    "!pip install -q tensorflow==1.15.2"
   ]
  },
  {
   "cell_type": "code",
   "execution_count": 1,
   "metadata": {},
   "outputs": [
    {
     "name": "stderr",
     "output_type": "stream",
     "text": [
      "ERROR:root:Internal Python error in the inspect module.\n",
      "Below is the traceback from this internal error.\n",
      "\n",
      "ERROR:root:Internal Python error in the inspect module.\n",
      "Below is the traceback from this internal error.\n",
      "\n"
     ]
    },
    {
     "name": "stdout",
     "output_type": "stream",
     "text": [
      "Traceback (most recent call last):\n",
      "  File \"C:\\Users\\HomeOffice\\anaconda3\\lib\\site-packages\\tensorflow_core\\python\\pywrap_tensorflow.py\", line 58, in <module>\n",
      "    from tensorflow.python.pywrap_tensorflow_internal import *\n",
      "  File \"C:\\Users\\HomeOffice\\anaconda3\\lib\\site-packages\\tensorflow_core\\python\\pywrap_tensorflow_internal.py\", line 28, in <module>\n",
      "    _pywrap_tensorflow_internal = swig_import_helper()\n",
      "  File \"C:\\Users\\HomeOffice\\anaconda3\\lib\\site-packages\\tensorflow_core\\python\\pywrap_tensorflow_internal.py\", line 24, in swig_import_helper\n",
      "    _mod = imp.load_module('_pywrap_tensorflow_internal', fp, pathname, description)\n",
      "  File \"C:\\Users\\HomeOffice\\anaconda3\\lib\\imp.py\", line 242, in load_module\n",
      "    return load_dynamic(name, filename, file)\n",
      "  File \"C:\\Users\\HomeOffice\\anaconda3\\lib\\imp.py\", line 342, in load_dynamic\n",
      "    return _load(spec)\n",
      "ImportError: DLL load failed with error code 3221225501\n",
      "\n",
      "During handling of the above exception, another exception occurred:\n",
      "\n",
      "Traceback (most recent call last):\n",
      "  File \"C:\\Users\\HomeOffice\\anaconda3\\lib\\site-packages\\IPython\\core\\interactiveshell.py\", line 3331, in run_code\n",
      "    exec(code_obj, self.user_global_ns, self.user_ns)\n",
      "  File \"<ipython-input-1-f258ed3e2ed1>\", line 6, in <module>\n",
      "    import tensorflow as tf\n",
      "  File \"C:\\Users\\HomeOffice\\anaconda3\\lib\\site-packages\\tensorflow\\__init__.py\", line 99, in <module>\n",
      "    from tensorflow_core import *\n",
      "  File \"C:\\Users\\HomeOffice\\anaconda3\\lib\\site-packages\\tensorflow_core\\__init__.py\", line 28, in <module>\n",
      "    from tensorflow.python import pywrap_tensorflow  # pylint: disable=unused-import\n",
      "  File \"C:\\Users\\HomeOffice\\anaconda3\\lib\\site-packages\\tensorflow\\__init__.py\", line 50, in __getattr__\n",
      "    module = self._load()\n",
      "  File \"C:\\Users\\HomeOffice\\anaconda3\\lib\\site-packages\\tensorflow\\__init__.py\", line 44, in _load\n",
      "    module = _importlib.import_module(self.__name__)\n",
      "  File \"C:\\Users\\HomeOffice\\anaconda3\\lib\\importlib\\__init__.py\", line 127, in import_module\n",
      "    return _bootstrap._gcd_import(name[level:], package, level)\n",
      "  File \"C:\\Users\\HomeOffice\\anaconda3\\lib\\site-packages\\tensorflow_core\\python\\__init__.py\", line 49, in <module>\n",
      "    from tensorflow.python import pywrap_tensorflow\n",
      "  File \"C:\\Users\\HomeOffice\\anaconda3\\lib\\site-packages\\tensorflow_core\\python\\pywrap_tensorflow.py\", line 74, in <module>\n",
      "    raise ImportError(msg)\n",
      "ImportError: Traceback (most recent call last):\n",
      "  File \"C:\\Users\\HomeOffice\\anaconda3\\lib\\site-packages\\tensorflow_core\\python\\pywrap_tensorflow.py\", line 58, in <module>\n",
      "    from tensorflow.python.pywrap_tensorflow_internal import *\n",
      "  File \"C:\\Users\\HomeOffice\\anaconda3\\lib\\site-packages\\tensorflow_core\\python\\pywrap_tensorflow_internal.py\", line 28, in <module>\n",
      "    _pywrap_tensorflow_internal = swig_import_helper()\n",
      "  File \"C:\\Users\\HomeOffice\\anaconda3\\lib\\site-packages\\tensorflow_core\\python\\pywrap_tensorflow_internal.py\", line 24, in swig_import_helper\n",
      "    _mod = imp.load_module('_pywrap_tensorflow_internal', fp, pathname, description)\n",
      "  File \"C:\\Users\\HomeOffice\\anaconda3\\lib\\imp.py\", line 242, in load_module\n",
      "    return load_dynamic(name, filename, file)\n",
      "  File \"C:\\Users\\HomeOffice\\anaconda3\\lib\\imp.py\", line 342, in load_dynamic\n",
      "    return _load(spec)\n",
      "ImportError: DLL load failed with error code 3221225501\n",
      "\n",
      "\n",
      "Failed to load the native TensorFlow runtime.\n",
      "\n",
      "See https://www.tensorflow.org/install/errors\n",
      "\n",
      "for some common reasons and solutions.  Include the entire stack trace\n",
      "above this error message when asking for help.\n",
      "\n",
      "During handling of the above exception, another exception occurred:\n",
      "\n",
      "Traceback (most recent call last):\n",
      "  File \"C:\\Users\\HomeOffice\\anaconda3\\lib\\site-packages\\IPython\\core\\interactiveshell.py\", line 2044, in showtraceback\n",
      "    stb = value._render_traceback_()\n",
      "AttributeError: 'ImportError' object has no attribute '_render_traceback_'\n",
      "\n",
      "During handling of the above exception, another exception occurred:\n",
      "\n",
      "Traceback (most recent call last):\n",
      "  File \"C:\\Users\\HomeOffice\\anaconda3\\lib\\site-packages\\tensorflow_core\\python\\pywrap_tensorflow.py\", line 58, in <module>\n",
      "    from tensorflow.python.pywrap_tensorflow_internal import *\n",
      "  File \"C:\\Users\\HomeOffice\\anaconda3\\lib\\site-packages\\tensorflow_core\\python\\pywrap_tensorflow_internal.py\", line 28, in <module>\n",
      "    _pywrap_tensorflow_internal = swig_import_helper()\n",
      "  File \"C:\\Users\\HomeOffice\\anaconda3\\lib\\site-packages\\tensorflow_core\\python\\pywrap_tensorflow_internal.py\", line 24, in swig_import_helper\n",
      "    _mod = imp.load_module('_pywrap_tensorflow_internal', fp, pathname, description)\n",
      "  File \"C:\\Users\\HomeOffice\\anaconda3\\lib\\imp.py\", line 242, in load_module\n",
      "    return load_dynamic(name, filename, file)\n",
      "  File \"C:\\Users\\HomeOffice\\anaconda3\\lib\\imp.py\", line 342, in load_dynamic\n",
      "    return _load(spec)\n",
      "ImportError: DLL load failed with error code 3221225501\n",
      "\n",
      "During handling of the above exception, another exception occurred:\n",
      "\n",
      "Traceback (most recent call last):\n",
      "  File \"C:\\Users\\HomeOffice\\anaconda3\\lib\\site-packages\\IPython\\core\\ultratb.py\", line 1151, in get_records\n",
      "    return _fixed_getinnerframes(etb, number_of_lines_of_context, tb_offset)\n",
      "  File \"C:\\Users\\HomeOffice\\anaconda3\\lib\\site-packages\\IPython\\core\\ultratb.py\", line 319, in wrapped\n",
      "    return f(*args, **kwargs)\n",
      "  File \"C:\\Users\\HomeOffice\\anaconda3\\lib\\site-packages\\IPython\\core\\ultratb.py\", line 353, in _fixed_getinnerframes\n",
      "    records = fix_frame_records_filenames(inspect.getinnerframes(etb, context))\n",
      "  File \"C:\\Users\\HomeOffice\\anaconda3\\lib\\inspect.py\", line 1502, in getinnerframes\n",
      "    frameinfo = (tb.tb_frame,) + getframeinfo(tb, context)\n",
      "  File \"C:\\Users\\HomeOffice\\anaconda3\\lib\\inspect.py\", line 1460, in getframeinfo\n",
      "    filename = getsourcefile(frame) or getfile(frame)\n",
      "  File \"C:\\Users\\HomeOffice\\anaconda3\\lib\\inspect.py\", line 696, in getsourcefile\n",
      "    if getattr(getmodule(object, filename), '__loader__', None) is not None:\n",
      "  File \"C:\\Users\\HomeOffice\\anaconda3\\lib\\inspect.py\", line 733, in getmodule\n",
      "    if ismodule(module) and hasattr(module, '__file__'):\n",
      "  File \"C:\\Users\\HomeOffice\\anaconda3\\lib\\site-packages\\tensorflow\\__init__.py\", line 50, in __getattr__\n",
      "    module = self._load()\n",
      "  File \"C:\\Users\\HomeOffice\\anaconda3\\lib\\site-packages\\tensorflow\\__init__.py\", line 44, in _load\n",
      "    module = _importlib.import_module(self.__name__)\n",
      "  File \"C:\\Users\\HomeOffice\\anaconda3\\lib\\importlib\\__init__.py\", line 127, in import_module\n",
      "    return _bootstrap._gcd_import(name[level:], package, level)\n",
      "  File \"<frozen importlib._bootstrap>\", line 1006, in _gcd_import\n",
      "  File \"<frozen importlib._bootstrap>\", line 983, in _find_and_load\n",
      "  File \"<frozen importlib._bootstrap>\", line 953, in _find_and_load_unlocked\n",
      "  File \"<frozen importlib._bootstrap>\", line 219, in _call_with_frames_removed\n",
      "  File \"<frozen importlib._bootstrap>\", line 1006, in _gcd_import\n",
      "  File \"<frozen importlib._bootstrap>\", line 983, in _find_and_load\n",
      "  File \"<frozen importlib._bootstrap>\", line 967, in _find_and_load_unlocked\n",
      "  File \"<frozen importlib._bootstrap>\", line 677, in _load_unlocked\n",
      "  File \"<frozen importlib._bootstrap_external>\", line 728, in exec_module\n",
      "  File \"<frozen importlib._bootstrap>\", line 219, in _call_with_frames_removed\n",
      "  File \"C:\\Users\\HomeOffice\\anaconda3\\lib\\site-packages\\tensorflow_core\\__init__.py\", line 28, in <module>\n",
      "    from tensorflow.python import pywrap_tensorflow  # pylint: disable=unused-import\n",
      "  File \"C:\\Users\\HomeOffice\\anaconda3\\lib\\site-packages\\tensorflow\\__init__.py\", line 50, in __getattr__\n",
      "    module = self._load()\n",
      "  File \"C:\\Users\\HomeOffice\\anaconda3\\lib\\site-packages\\tensorflow\\__init__.py\", line 44, in _load\n",
      "    module = _importlib.import_module(self.__name__)\n",
      "  File \"C:\\Users\\HomeOffice\\anaconda3\\lib\\importlib\\__init__.py\", line 127, in import_module\n",
      "    return _bootstrap._gcd_import(name[level:], package, level)\n",
      "  File \"C:\\Users\\HomeOffice\\anaconda3\\lib\\site-packages\\tensorflow_core\\python\\__init__.py\", line 49, in <module>\n",
      "    from tensorflow.python import pywrap_tensorflow\n",
      "  File \"C:\\Users\\HomeOffice\\anaconda3\\lib\\site-packages\\tensorflow_core\\python\\pywrap_tensorflow.py\", line 74, in <module>\n",
      "    raise ImportError(msg)\n",
      "ImportError: Traceback (most recent call last):\n",
      "  File \"C:\\Users\\HomeOffice\\anaconda3\\lib\\site-packages\\tensorflow_core\\python\\pywrap_tensorflow.py\", line 58, in <module>\n",
      "    from tensorflow.python.pywrap_tensorflow_internal import *\n",
      "  File \"C:\\Users\\HomeOffice\\anaconda3\\lib\\site-packages\\tensorflow_core\\python\\pywrap_tensorflow_internal.py\", line 28, in <module>\n",
      "    _pywrap_tensorflow_internal = swig_import_helper()\n",
      "  File \"C:\\Users\\HomeOffice\\anaconda3\\lib\\site-packages\\tensorflow_core\\python\\pywrap_tensorflow_internal.py\", line 24, in swig_import_helper\n",
      "    _mod = imp.load_module('_pywrap_tensorflow_internal', fp, pathname, description)\n",
      "  File \"C:\\Users\\HomeOffice\\anaconda3\\lib\\imp.py\", line 242, in load_module\n",
      "    return load_dynamic(name, filename, file)\n",
      "  File \"C:\\Users\\HomeOffice\\anaconda3\\lib\\imp.py\", line 342, in load_dynamic\n",
      "    return _load(spec)\n",
      "ImportError: DLL load failed with error code 3221225501\n",
      "\n",
      "During handling of the above exception, another exception occurred:\n",
      "\n",
      "Traceback (most recent call last):\n",
      "  File \"C:\\Users\\HomeOffice\\anaconda3\\lib\\site-packages\\IPython\\core\\interactiveshell.py\", line 3331, in run_code\n",
      "    exec(code_obj, self.user_global_ns, self.user_ns)\n",
      "  File \"<ipython-input-1-f258ed3e2ed1>\", line 6, in <module>\n",
      "    import tensorflow as tf\n",
      "  File \"C:\\Users\\HomeOffice\\anaconda3\\lib\\site-packages\\tensorflow\\__init__.py\", line 99, in <module>\n",
      "    from tensorflow_core import *\n",
      "  File \"C:\\Users\\HomeOffice\\anaconda3\\lib\\site-packages\\tensorflow_core\\__init__.py\", line 28, in <module>\n",
      "    from tensorflow.python import pywrap_tensorflow  # pylint: disable=unused-import\n",
      "  File \"C:\\Users\\HomeOffice\\anaconda3\\lib\\site-packages\\tensorflow\\__init__.py\", line 50, in __getattr__\n",
      "    module = self._load()\n",
      "  File \"C:\\Users\\HomeOffice\\anaconda3\\lib\\site-packages\\tensorflow\\__init__.py\", line 44, in _load\n",
      "    module = _importlib.import_module(self.__name__)\n",
      "  File \"C:\\Users\\HomeOffice\\anaconda3\\lib\\importlib\\__init__.py\", line 127, in import_module\n",
      "    return _bootstrap._gcd_import(name[level:], package, level)\n",
      "  File \"C:\\Users\\HomeOffice\\anaconda3\\lib\\site-packages\\tensorflow_core\\python\\__init__.py\", line 49, in <module>\n",
      "    from tensorflow.python import pywrap_tensorflow\n",
      "  File \"C:\\Users\\HomeOffice\\anaconda3\\lib\\site-packages\\tensorflow_core\\python\\pywrap_tensorflow.py\", line 74, in <module>\n",
      "    raise ImportError(msg)\n",
      "ImportError: Traceback (most recent call last):\n",
      "  File \"C:\\Users\\HomeOffice\\anaconda3\\lib\\site-packages\\tensorflow_core\\python\\pywrap_tensorflow.py\", line 58, in <module>\n",
      "    from tensorflow.python.pywrap_tensorflow_internal import *\n",
      "  File \"C:\\Users\\HomeOffice\\anaconda3\\lib\\site-packages\\tensorflow_core\\python\\pywrap_tensorflow_internal.py\", line 28, in <module>\n",
      "    _pywrap_tensorflow_internal = swig_import_helper()\n",
      "  File \"C:\\Users\\HomeOffice\\anaconda3\\lib\\site-packages\\tensorflow_core\\python\\pywrap_tensorflow_internal.py\", line 24, in swig_import_helper\n",
      "    _mod = imp.load_module('_pywrap_tensorflow_internal', fp, pathname, description)\n",
      "  File \"C:\\Users\\HomeOffice\\anaconda3\\lib\\imp.py\", line 242, in load_module\n",
      "    return load_dynamic(name, filename, file)\n",
      "  File \"C:\\Users\\HomeOffice\\anaconda3\\lib\\imp.py\", line 342, in load_dynamic\n",
      "    return _load(spec)\n",
      "ImportError: DLL load failed with error code 3221225501\n",
      "\n",
      "\n",
      "Failed to load the native TensorFlow runtime.\n",
      "\n",
      "See https://www.tensorflow.org/install/errors\n",
      "\n",
      "for some common reasons and solutions.  Include the entire stack trace\n",
      "above this error message when asking for help.\n",
      "\n",
      "During handling of the above exception, another exception occurred:\n",
      "\n",
      "Traceback (most recent call last):\n",
      "  File \"C:\\Users\\HomeOffice\\anaconda3\\lib\\site-packages\\IPython\\core\\interactiveshell.py\", line 2044, in showtraceback\n",
      "    stb = value._render_traceback_()\n",
      "AttributeError: 'ImportError' object has no attribute '_render_traceback_'\n",
      "\n",
      "During handling of the above exception, another exception occurred:\n",
      "\n",
      "Traceback (most recent call last):\n",
      "  File \"C:\\Users\\HomeOffice\\anaconda3\\lib\\site-packages\\tensorflow_core\\python\\pywrap_tensorflow.py\", line 58, in <module>\n",
      "    from tensorflow.python.pywrap_tensorflow_internal import *\n",
      "  File \"C:\\Users\\HomeOffice\\anaconda3\\lib\\site-packages\\tensorflow_core\\python\\pywrap_tensorflow_internal.py\", line 28, in <module>\n",
      "    _pywrap_tensorflow_internal = swig_import_helper()\n",
      "  File \"C:\\Users\\HomeOffice\\anaconda3\\lib\\site-packages\\tensorflow_core\\python\\pywrap_tensorflow_internal.py\", line 24, in swig_import_helper\n",
      "    _mod = imp.load_module('_pywrap_tensorflow_internal', fp, pathname, description)\n",
      "  File \"C:\\Users\\HomeOffice\\anaconda3\\lib\\imp.py\", line 242, in load_module\n",
      "    return load_dynamic(name, filename, file)\n",
      "  File \"C:\\Users\\HomeOffice\\anaconda3\\lib\\imp.py\", line 342, in load_dynamic\n",
      "    return _load(spec)\n",
      "ImportError: DLL load failed with error code 3221225501\n",
      "\n",
      "\n",
      "Failed to load the native TensorFlow runtime.\n",
      "\n",
      "See https://www.tensorflow.org/install/errors\n",
      "\n",
      "for some common reasons and solutions.  Include the entire stack trace\n",
      "above this error message when asking for help.\n",
      "Traceback (most recent call last):\n",
      "  File \"C:\\Users\\HomeOffice\\anaconda3\\lib\\site-packages\\tensorflow_core\\python\\pywrap_tensorflow.py\", line 58, in <module>\n",
      "    from tensorflow.python.pywrap_tensorflow_internal import *\n",
      "  File \"C:\\Users\\HomeOffice\\anaconda3\\lib\\site-packages\\tensorflow_core\\python\\pywrap_tensorflow_internal.py\", line 28, in <module>\n",
      "    _pywrap_tensorflow_internal = swig_import_helper()\n",
      "  File \"C:\\Users\\HomeOffice\\anaconda3\\lib\\site-packages\\tensorflow_core\\python\\pywrap_tensorflow_internal.py\", line 24, in swig_import_helper\n",
      "    _mod = imp.load_module('_pywrap_tensorflow_internal', fp, pathname, description)\n",
      "  File \"C:\\Users\\HomeOffice\\anaconda3\\lib\\imp.py\", line 242, in load_module\n",
      "    return load_dynamic(name, filename, file)\n",
      "  File \"C:\\Users\\HomeOffice\\anaconda3\\lib\\imp.py\", line 342, in load_dynamic\n",
      "    return _load(spec)\n",
      "ImportError: DLL load failed with error code 3221225501\n",
      "\n",
      "During handling of the above exception, another exception occurred:\n",
      "\n",
      "Traceback (most recent call last):\n",
      "  File \"C:\\Users\\HomeOffice\\anaconda3\\lib\\site-packages\\IPython\\core\\interactiveshell.py\", line 3331, in run_code\n",
      "    exec(code_obj, self.user_global_ns, self.user_ns)\n",
      "  File \"<ipython-input-1-f258ed3e2ed1>\", line 6, in <module>\n",
      "    import tensorflow as tf\n",
      "  File \"C:\\Users\\HomeOffice\\anaconda3\\lib\\site-packages\\tensorflow\\__init__.py\", line 99, in <module>\n",
      "    from tensorflow_core import *\n",
      "  File \"C:\\Users\\HomeOffice\\anaconda3\\lib\\site-packages\\tensorflow_core\\__init__.py\", line 28, in <module>\n",
      "    from tensorflow.python import pywrap_tensorflow  # pylint: disable=unused-import\n",
      "  File \"C:\\Users\\HomeOffice\\anaconda3\\lib\\site-packages\\tensorflow\\__init__.py\", line 50, in __getattr__\n",
      "    module = self._load()\n",
      "  File \"C:\\Users\\HomeOffice\\anaconda3\\lib\\site-packages\\tensorflow\\__init__.py\", line 44, in _load\n",
      "    module = _importlib.import_module(self.__name__)\n",
      "  File \"C:\\Users\\HomeOffice\\anaconda3\\lib\\importlib\\__init__.py\", line 127, in import_module\n",
      "    return _bootstrap._gcd_import(name[level:], package, level)\n",
      "  File \"C:\\Users\\HomeOffice\\anaconda3\\lib\\site-packages\\tensorflow_core\\python\\__init__.py\", line 49, in <module>\n",
      "    from tensorflow.python import pywrap_tensorflow\n",
      "  File \"C:\\Users\\HomeOffice\\anaconda3\\lib\\site-packages\\tensorflow_core\\python\\pywrap_tensorflow.py\", line 74, in <module>\n",
      "    raise ImportError(msg)\n",
      "ImportError: Traceback (most recent call last):\n",
      "  File \"C:\\Users\\HomeOffice\\anaconda3\\lib\\site-packages\\tensorflow_core\\python\\pywrap_tensorflow.py\", line 58, in <module>\n",
      "    from tensorflow.python.pywrap_tensorflow_internal import *\n",
      "  File \"C:\\Users\\HomeOffice\\anaconda3\\lib\\site-packages\\tensorflow_core\\python\\pywrap_tensorflow_internal.py\", line 28, in <module>\n",
      "    _pywrap_tensorflow_internal = swig_import_helper()\n",
      "  File \"C:\\Users\\HomeOffice\\anaconda3\\lib\\site-packages\\tensorflow_core\\python\\pywrap_tensorflow_internal.py\", line 24, in swig_import_helper\n",
      "    _mod = imp.load_module('_pywrap_tensorflow_internal', fp, pathname, description)\n",
      "  File \"C:\\Users\\HomeOffice\\anaconda3\\lib\\imp.py\", line 242, in load_module\n",
      "    return load_dynamic(name, filename, file)\n",
      "  File \"C:\\Users\\HomeOffice\\anaconda3\\lib\\imp.py\", line 342, in load_dynamic\n",
      "    return _load(spec)\n",
      "ImportError: DLL load failed with error code 3221225501\n",
      "\n",
      "\n",
      "Failed to load the native TensorFlow runtime.\n",
      "\n",
      "See https://www.tensorflow.org/install/errors\n",
      "\n",
      "for some common reasons and solutions.  Include the entire stack trace\n",
      "above this error message when asking for help.\n",
      "\n",
      "During handling of the above exception, another exception occurred:\n",
      "\n",
      "Traceback (most recent call last):\n",
      "  File \"C:\\Users\\HomeOffice\\anaconda3\\lib\\site-packages\\IPython\\core\\interactiveshell.py\", line 2044, in showtraceback\n",
      "    stb = value._render_traceback_()\n",
      "AttributeError: 'ImportError' object has no attribute '_render_traceback_'\n",
      "\n",
      "During handling of the above exception, another exception occurred:\n",
      "\n",
      "Traceback (most recent call last):\n",
      "  File \"C:\\Users\\HomeOffice\\anaconda3\\lib\\site-packages\\IPython\\core\\interactiveshell.py\", line 3254, in run_ast_nodes\n",
      "    if (await self.run_code(code, result,  async_=asy)):\n",
      "  File \"C:\\Users\\HomeOffice\\anaconda3\\lib\\site-packages\\IPython\\core\\interactiveshell.py\", line 3348, in run_code\n",
      "    self.showtraceback(running_compiled_code=True)\n",
      "  File \"C:\\Users\\HomeOffice\\anaconda3\\lib\\site-packages\\IPython\\core\\interactiveshell.py\", line 2047, in showtraceback\n",
      "    value, tb, tb_offset=tb_offset)\n",
      "  File \"C:\\Users\\HomeOffice\\anaconda3\\lib\\site-packages\\IPython\\core\\ultratb.py\", line 1418, in structured_traceback\n",
      "    self, etype, value, tb, tb_offset, number_of_lines_of_context)\n",
      "  File \"C:\\Users\\HomeOffice\\anaconda3\\lib\\site-packages\\IPython\\core\\ultratb.py\", line 1318, in structured_traceback\n",
      "    self, etype, value, tb, tb_offset, number_of_lines_of_context\n",
      "  File \"C:\\Users\\HomeOffice\\anaconda3\\lib\\site-packages\\IPython\\core\\ultratb.py\", line 1186, in structured_traceback\n",
      "    formatted_exceptions += self.prepare_chained_exception_message(evalue.__cause__)\n",
      "TypeError: can only concatenate str (not \"list\") to str\n",
      "\n",
      "During handling of the above exception, another exception occurred:\n",
      "\n",
      "Traceback (most recent call last):\n",
      "  File \"C:\\Users\\HomeOffice\\anaconda3\\lib\\site-packages\\IPython\\core\\interactiveshell.py\", line 2044, in showtraceback\n",
      "    stb = value._render_traceback_()\n",
      "AttributeError: 'TypeError' object has no attribute '_render_traceback_'\n",
      "\n",
      "During handling of the above exception, another exception occurred:\n",
      "\n",
      "Traceback (most recent call last):\n",
      "  File \"C:\\Users\\HomeOffice\\anaconda3\\lib\\site-packages\\tensorflow_core\\python\\pywrap_tensorflow.py\", line 58, in <module>\n",
      "    from tensorflow.python.pywrap_tensorflow_internal import *\n",
      "  File \"C:\\Users\\HomeOffice\\anaconda3\\lib\\site-packages\\tensorflow_core\\python\\pywrap_tensorflow_internal.py\", line 28, in <module>\n",
      "    _pywrap_tensorflow_internal = swig_import_helper()\n",
      "  File \"C:\\Users\\HomeOffice\\anaconda3\\lib\\site-packages\\tensorflow_core\\python\\pywrap_tensorflow_internal.py\", line 24, in swig_import_helper\n",
      "    _mod = imp.load_module('_pywrap_tensorflow_internal', fp, pathname, description)\n",
      "  File \"C:\\Users\\HomeOffice\\anaconda3\\lib\\imp.py\", line 242, in load_module\n",
      "    return load_dynamic(name, filename, file)\n",
      "  File \"C:\\Users\\HomeOffice\\anaconda3\\lib\\imp.py\", line 342, in load_dynamic\n",
      "    return _load(spec)\n",
      "ImportError: DLL load failed with error code 3221225501\n",
      "\n",
      "During handling of the above exception, another exception occurred:\n",
      "\n",
      "Traceback (most recent call last):\n",
      "  File \"C:\\Users\\HomeOffice\\anaconda3\\lib\\site-packages\\IPython\\core\\ultratb.py\", line 1151, in get_records\n",
      "    return _fixed_getinnerframes(etb, number_of_lines_of_context, tb_offset)\n",
      "  File \"C:\\Users\\HomeOffice\\anaconda3\\lib\\site-packages\\IPython\\core\\ultratb.py\", line 319, in wrapped\n",
      "    return f(*args, **kwargs)\n",
      "  File \"C:\\Users\\HomeOffice\\anaconda3\\lib\\site-packages\\IPython\\core\\ultratb.py\", line 353, in _fixed_getinnerframes\n",
      "    records = fix_frame_records_filenames(inspect.getinnerframes(etb, context))\n",
      "  File \"C:\\Users\\HomeOffice\\anaconda3\\lib\\inspect.py\", line 1502, in getinnerframes\n",
      "    frameinfo = (tb.tb_frame,) + getframeinfo(tb, context)\n",
      "  File \"C:\\Users\\HomeOffice\\anaconda3\\lib\\inspect.py\", line 1460, in getframeinfo\n",
      "    filename = getsourcefile(frame) or getfile(frame)\n",
      "  File \"C:\\Users\\HomeOffice\\anaconda3\\lib\\inspect.py\", line 696, in getsourcefile\n",
      "    if getattr(getmodule(object, filename), '__loader__', None) is not None:\n",
      "  File \"C:\\Users\\HomeOffice\\anaconda3\\lib\\inspect.py\", line 733, in getmodule\n",
      "    if ismodule(module) and hasattr(module, '__file__'):\n",
      "  File \"C:\\Users\\HomeOffice\\anaconda3\\lib\\site-packages\\tensorflow\\__init__.py\", line 50, in __getattr__\n",
      "    module = self._load()\n",
      "  File \"C:\\Users\\HomeOffice\\anaconda3\\lib\\site-packages\\tensorflow\\__init__.py\", line 44, in _load\n",
      "    module = _importlib.import_module(self.__name__)\n",
      "  File \"C:\\Users\\HomeOffice\\anaconda3\\lib\\importlib\\__init__.py\", line 127, in import_module\n",
      "    return _bootstrap._gcd_import(name[level:], package, level)\n",
      "  File \"<frozen importlib._bootstrap>\", line 1006, in _gcd_import\n",
      "  File \"<frozen importlib._bootstrap>\", line 983, in _find_and_load\n",
      "  File \"<frozen importlib._bootstrap>\", line 953, in _find_and_load_unlocked\n",
      "  File \"<frozen importlib._bootstrap>\", line 219, in _call_with_frames_removed\n",
      "  File \"<frozen importlib._bootstrap>\", line 1006, in _gcd_import\n",
      "  File \"<frozen importlib._bootstrap>\", line 983, in _find_and_load\n",
      "  File \"<frozen importlib._bootstrap>\", line 967, in _find_and_load_unlocked\n",
      "  File \"<frozen importlib._bootstrap>\", line 677, in _load_unlocked\n",
      "  File \"<frozen importlib._bootstrap_external>\", line 728, in exec_module\n",
      "  File \"<frozen importlib._bootstrap>\", line 219, in _call_with_frames_removed\n",
      "  File \"C:\\Users\\HomeOffice\\anaconda3\\lib\\site-packages\\tensorflow_core\\__init__.py\", line 28, in <module>\n",
      "    from tensorflow.python import pywrap_tensorflow  # pylint: disable=unused-import\n",
      "  File \"C:\\Users\\HomeOffice\\anaconda3\\lib\\site-packages\\tensorflow\\__init__.py\", line 50, in __getattr__\n",
      "    module = self._load()\n",
      "  File \"C:\\Users\\HomeOffice\\anaconda3\\lib\\site-packages\\tensorflow\\__init__.py\", line 44, in _load\n",
      "    module = _importlib.import_module(self.__name__)\n",
      "  File \"C:\\Users\\HomeOffice\\anaconda3\\lib\\importlib\\__init__.py\", line 127, in import_module\n",
      "    return _bootstrap._gcd_import(name[level:], package, level)\n",
      "  File \"C:\\Users\\HomeOffice\\anaconda3\\lib\\site-packages\\tensorflow_core\\python\\__init__.py\", line 49, in <module>\n",
      "    from tensorflow.python import pywrap_tensorflow\n",
      "  File \"C:\\Users\\HomeOffice\\anaconda3\\lib\\site-packages\\tensorflow_core\\python\\pywrap_tensorflow.py\", line 74, in <module>\n",
      "    raise ImportError(msg)\n",
      "ImportError: Traceback (most recent call last):\n",
      "  File \"C:\\Users\\HomeOffice\\anaconda3\\lib\\site-packages\\tensorflow_core\\python\\pywrap_tensorflow.py\", line 58, in <module>\n",
      "    from tensorflow.python.pywrap_tensorflow_internal import *\n",
      "  File \"C:\\Users\\HomeOffice\\anaconda3\\lib\\site-packages\\tensorflow_core\\python\\pywrap_tensorflow_internal.py\", line 28, in <module>\n",
      "    _pywrap_tensorflow_internal = swig_import_helper()\n",
      "  File \"C:\\Users\\HomeOffice\\anaconda3\\lib\\site-packages\\tensorflow_core\\python\\pywrap_tensorflow_internal.py\", line 24, in swig_import_helper\n",
      "    _mod = imp.load_module('_pywrap_tensorflow_internal', fp, pathname, description)\n",
      "  File \"C:\\Users\\HomeOffice\\anaconda3\\lib\\imp.py\", line 242, in load_module\n",
      "    return load_dynamic(name, filename, file)\n",
      "  File \"C:\\Users\\HomeOffice\\anaconda3\\lib\\imp.py\", line 342, in load_dynamic\n",
      "    return _load(spec)\n",
      "ImportError: DLL load failed with error code 3221225501\n",
      "\n",
      "During handling of the above exception, another exception occurred:\n",
      "\n",
      "Traceback (most recent call last):\n",
      "  File \"C:\\Users\\HomeOffice\\anaconda3\\lib\\site-packages\\IPython\\core\\interactiveshell.py\", line 3331, in run_code\n",
      "    exec(code_obj, self.user_global_ns, self.user_ns)\n",
      "  File \"<ipython-input-1-f258ed3e2ed1>\", line 6, in <module>\n",
      "    import tensorflow as tf\n",
      "  File \"C:\\Users\\HomeOffice\\anaconda3\\lib\\site-packages\\tensorflow\\__init__.py\", line 99, in <module>\n",
      "    from tensorflow_core import *\n",
      "  File \"C:\\Users\\HomeOffice\\anaconda3\\lib\\site-packages\\tensorflow_core\\__init__.py\", line 28, in <module>\n",
      "    from tensorflow.python import pywrap_tensorflow  # pylint: disable=unused-import\n",
      "  File \"C:\\Users\\HomeOffice\\anaconda3\\lib\\site-packages\\tensorflow\\__init__.py\", line 50, in __getattr__\n",
      "    module = self._load()\n",
      "  File \"C:\\Users\\HomeOffice\\anaconda3\\lib\\site-packages\\tensorflow\\__init__.py\", line 44, in _load\n",
      "    module = _importlib.import_module(self.__name__)\n",
      "  File \"C:\\Users\\HomeOffice\\anaconda3\\lib\\importlib\\__init__.py\", line 127, in import_module\n",
      "    return _bootstrap._gcd_import(name[level:], package, level)\n",
      "  File \"C:\\Users\\HomeOffice\\anaconda3\\lib\\site-packages\\tensorflow_core\\python\\__init__.py\", line 49, in <module>\n",
      "    from tensorflow.python import pywrap_tensorflow\n",
      "  File \"C:\\Users\\HomeOffice\\anaconda3\\lib\\site-packages\\tensorflow_core\\python\\pywrap_tensorflow.py\", line 74, in <module>\n",
      "    raise ImportError(msg)\n",
      "ImportError: Traceback (most recent call last):\n",
      "  File \"C:\\Users\\HomeOffice\\anaconda3\\lib\\site-packages\\tensorflow_core\\python\\pywrap_tensorflow.py\", line 58, in <module>\n",
      "    from tensorflow.python.pywrap_tensorflow_internal import *\n",
      "  File \"C:\\Users\\HomeOffice\\anaconda3\\lib\\site-packages\\tensorflow_core\\python\\pywrap_tensorflow_internal.py\", line 28, in <module>\n",
      "    _pywrap_tensorflow_internal = swig_import_helper()\n",
      "  File \"C:\\Users\\HomeOffice\\anaconda3\\lib\\site-packages\\tensorflow_core\\python\\pywrap_tensorflow_internal.py\", line 24, in swig_import_helper\n",
      "    _mod = imp.load_module('_pywrap_tensorflow_internal', fp, pathname, description)\n",
      "  File \"C:\\Users\\HomeOffice\\anaconda3\\lib\\imp.py\", line 242, in load_module\n",
      "    return load_dynamic(name, filename, file)\n",
      "  File \"C:\\Users\\HomeOffice\\anaconda3\\lib\\imp.py\", line 342, in load_dynamic\n",
      "    return _load(spec)\n",
      "ImportError: DLL load failed with error code 3221225501\n",
      "\n",
      "\n",
      "Failed to load the native TensorFlow runtime.\n",
      "\n",
      "See https://www.tensorflow.org/install/errors\n",
      "\n",
      "for some common reasons and solutions.  Include the entire stack trace\n",
      "above this error message when asking for help.\n",
      "\n",
      "During handling of the above exception, another exception occurred:\n",
      "\n",
      "Traceback (most recent call last):\n",
      "  File \"C:\\Users\\HomeOffice\\anaconda3\\lib\\site-packages\\IPython\\core\\interactiveshell.py\", line 2044, in showtraceback\n",
      "    stb = value._render_traceback_()\n",
      "AttributeError: 'ImportError' object has no attribute '_render_traceback_'\n",
      "\n",
      "During handling of the above exception, another exception occurred:\n",
      "\n",
      "Traceback (most recent call last):\n",
      "  File \"C:\\Users\\HomeOffice\\anaconda3\\lib\\site-packages\\IPython\\core\\interactiveshell.py\", line 3254, in run_ast_nodes\n",
      "    if (await self.run_code(code, result,  async_=asy)):\n",
      "  File \"C:\\Users\\HomeOffice\\anaconda3\\lib\\site-packages\\IPython\\core\\interactiveshell.py\", line 3348, in run_code\n",
      "    self.showtraceback(running_compiled_code=True)\n",
      "  File \"C:\\Users\\HomeOffice\\anaconda3\\lib\\site-packages\\IPython\\core\\interactiveshell.py\", line 2047, in showtraceback\n",
      "    value, tb, tb_offset=tb_offset)\n",
      "  File \"C:\\Users\\HomeOffice\\anaconda3\\lib\\site-packages\\IPython\\core\\ultratb.py\", line 1418, in structured_traceback\n",
      "    self, etype, value, tb, tb_offset, number_of_lines_of_context)\n",
      "  File \"C:\\Users\\HomeOffice\\anaconda3\\lib\\site-packages\\IPython\\core\\ultratb.py\", line 1318, in structured_traceback\n",
      "    self, etype, value, tb, tb_offset, number_of_lines_of_context\n",
      "  File \"C:\\Users\\HomeOffice\\anaconda3\\lib\\site-packages\\IPython\\core\\ultratb.py\", line 1186, in structured_traceback\n",
      "    formatted_exceptions += self.prepare_chained_exception_message(evalue.__cause__)\n",
      "TypeError: can only concatenate str (not \"list\") to str\n",
      "\n",
      "During handling of the above exception, another exception occurred:\n",
      "\n",
      "Traceback (most recent call last):\n",
      "  File \"C:\\Users\\HomeOffice\\anaconda3\\lib\\site-packages\\IPython\\core\\interactiveshell.py\", line 2044, in showtraceback\n",
      "    stb = value._render_traceback_()\n",
      "AttributeError: 'TypeError' object has no attribute '_render_traceback_'\n",
      "\n",
      "During handling of the above exception, another exception occurred:\n",
      "\n",
      "Traceback (most recent call last):\n",
      "  File \"C:\\Users\\HomeOffice\\anaconda3\\lib\\site-packages\\tensorflow_core\\python\\pywrap_tensorflow.py\", line 58, in <module>\n",
      "    from tensorflow.python.pywrap_tensorflow_internal import *\n",
      "  File \"C:\\Users\\HomeOffice\\anaconda3\\lib\\site-packages\\tensorflow_core\\python\\pywrap_tensorflow_internal.py\", line 28, in <module>\n",
      "    _pywrap_tensorflow_internal = swig_import_helper()\n",
      "  File \"C:\\Users\\HomeOffice\\anaconda3\\lib\\site-packages\\tensorflow_core\\python\\pywrap_tensorflow_internal.py\", line 24, in swig_import_helper\n",
      "    _mod = imp.load_module('_pywrap_tensorflow_internal', fp, pathname, description)\n",
      "  File \"C:\\Users\\HomeOffice\\anaconda3\\lib\\imp.py\", line 242, in load_module\n",
      "    return load_dynamic(name, filename, file)\n",
      "  File \"C:\\Users\\HomeOffice\\anaconda3\\lib\\imp.py\", line 342, in load_dynamic\n",
      "    return _load(spec)\n",
      "ImportError: DLL load failed with error code 3221225501\n",
      "\n",
      "\n",
      "Failed to load the native TensorFlow runtime.\n",
      "\n",
      "See https://www.tensorflow.org/install/errors\n",
      "\n",
      "for some common reasons and solutions.  Include the entire stack trace\n",
      "above this error message when asking for help.\n"
     ]
    },
    {
     "ename": "TypeError",
     "evalue": "can only concatenate str (not \"list\") to str",
     "output_type": "error",
     "traceback": [
      "\u001b[1;31m---------------------------------------------------------------------------\u001b[0m",
      "\u001b[1;31mImportError\u001b[0m                               Traceback (most recent call last)",
      "\u001b[1;32m~\\anaconda3\\lib\\site-packages\\tensorflow_core\\python\\pywrap_tensorflow.py\u001b[0m in \u001b[0;36m<module>\u001b[1;34m\u001b[0m\n\u001b[0;32m     57\u001b[0m \u001b[1;33m\u001b[0m\u001b[0m\n\u001b[1;32m---> 58\u001b[1;33m   \u001b[1;32mfrom\u001b[0m \u001b[0mtensorflow\u001b[0m\u001b[1;33m.\u001b[0m\u001b[0mpython\u001b[0m\u001b[1;33m.\u001b[0m\u001b[0mpywrap_tensorflow_internal\u001b[0m \u001b[1;32mimport\u001b[0m \u001b[1;33m*\u001b[0m\u001b[1;33m\u001b[0m\u001b[1;33m\u001b[0m\u001b[0m\n\u001b[0m\u001b[0;32m     59\u001b[0m   \u001b[1;32mfrom\u001b[0m \u001b[0mtensorflow\u001b[0m\u001b[1;33m.\u001b[0m\u001b[0mpython\u001b[0m\u001b[1;33m.\u001b[0m\u001b[0mpywrap_tensorflow_internal\u001b[0m \u001b[1;32mimport\u001b[0m \u001b[0m__version__\u001b[0m\u001b[1;33m\u001b[0m\u001b[1;33m\u001b[0m\u001b[0m\n",
      "\u001b[1;32m~\\anaconda3\\lib\\site-packages\\tensorflow_core\\python\\pywrap_tensorflow_internal.py\u001b[0m in \u001b[0;36m<module>\u001b[1;34m\u001b[0m\n\u001b[0;32m     27\u001b[0m             \u001b[1;32mreturn\u001b[0m \u001b[0m_mod\u001b[0m\u001b[1;33m\u001b[0m\u001b[1;33m\u001b[0m\u001b[0m\n\u001b[1;32m---> 28\u001b[1;33m     \u001b[0m_pywrap_tensorflow_internal\u001b[0m \u001b[1;33m=\u001b[0m \u001b[0mswig_import_helper\u001b[0m\u001b[1;33m(\u001b[0m\u001b[1;33m)\u001b[0m\u001b[1;33m\u001b[0m\u001b[1;33m\u001b[0m\u001b[0m\n\u001b[0m\u001b[0;32m     29\u001b[0m     \u001b[1;32mdel\u001b[0m \u001b[0mswig_import_helper\u001b[0m\u001b[1;33m\u001b[0m\u001b[1;33m\u001b[0m\u001b[0m\n",
      "\u001b[1;32m~\\anaconda3\\lib\\site-packages\\tensorflow_core\\python\\pywrap_tensorflow_internal.py\u001b[0m in \u001b[0;36mswig_import_helper\u001b[1;34m()\u001b[0m\n\u001b[0;32m     23\u001b[0m             \u001b[1;32mtry\u001b[0m\u001b[1;33m:\u001b[0m\u001b[1;33m\u001b[0m\u001b[1;33m\u001b[0m\u001b[0m\n\u001b[1;32m---> 24\u001b[1;33m                 \u001b[0m_mod\u001b[0m \u001b[1;33m=\u001b[0m \u001b[0mimp\u001b[0m\u001b[1;33m.\u001b[0m\u001b[0mload_module\u001b[0m\u001b[1;33m(\u001b[0m\u001b[1;34m'_pywrap_tensorflow_internal'\u001b[0m\u001b[1;33m,\u001b[0m \u001b[0mfp\u001b[0m\u001b[1;33m,\u001b[0m \u001b[0mpathname\u001b[0m\u001b[1;33m,\u001b[0m \u001b[0mdescription\u001b[0m\u001b[1;33m)\u001b[0m\u001b[1;33m\u001b[0m\u001b[1;33m\u001b[0m\u001b[0m\n\u001b[0m\u001b[0;32m     25\u001b[0m             \u001b[1;32mfinally\u001b[0m\u001b[1;33m:\u001b[0m\u001b[1;33m\u001b[0m\u001b[1;33m\u001b[0m\u001b[0m\n",
      "\u001b[1;32m~\\anaconda3\\lib\\imp.py\u001b[0m in \u001b[0;36mload_module\u001b[1;34m(name, file, filename, details)\u001b[0m\n\u001b[0;32m    241\u001b[0m         \u001b[1;32melse\u001b[0m\u001b[1;33m:\u001b[0m\u001b[1;33m\u001b[0m\u001b[1;33m\u001b[0m\u001b[0m\n\u001b[1;32m--> 242\u001b[1;33m             \u001b[1;32mreturn\u001b[0m \u001b[0mload_dynamic\u001b[0m\u001b[1;33m(\u001b[0m\u001b[0mname\u001b[0m\u001b[1;33m,\u001b[0m \u001b[0mfilename\u001b[0m\u001b[1;33m,\u001b[0m \u001b[0mfile\u001b[0m\u001b[1;33m)\u001b[0m\u001b[1;33m\u001b[0m\u001b[1;33m\u001b[0m\u001b[0m\n\u001b[0m\u001b[0;32m    243\u001b[0m     \u001b[1;32melif\u001b[0m \u001b[0mtype_\u001b[0m \u001b[1;33m==\u001b[0m \u001b[0mPKG_DIRECTORY\u001b[0m\u001b[1;33m:\u001b[0m\u001b[1;33m\u001b[0m\u001b[1;33m\u001b[0m\u001b[0m\n",
      "\u001b[1;32m~\\anaconda3\\lib\\imp.py\u001b[0m in \u001b[0;36mload_dynamic\u001b[1;34m(name, path, file)\u001b[0m\n\u001b[0;32m    341\u001b[0m             name=name, loader=loader, origin=path)\n\u001b[1;32m--> 342\u001b[1;33m         \u001b[1;32mreturn\u001b[0m \u001b[0m_load\u001b[0m\u001b[1;33m(\u001b[0m\u001b[0mspec\u001b[0m\u001b[1;33m)\u001b[0m\u001b[1;33m\u001b[0m\u001b[1;33m\u001b[0m\u001b[0m\n\u001b[0m\u001b[0;32m    343\u001b[0m \u001b[1;33m\u001b[0m\u001b[0m\n",
      "\u001b[1;31mImportError\u001b[0m: DLL load failed with error code 3221225501",
      "\nDuring handling of the above exception, another exception occurred:\n",
      "\nDuring handling of the above exception, another exception occurred:\n",
      "\u001b[1;31mAttributeError\u001b[0m                            Traceback (most recent call last)",
      "\u001b[1;32m~\\anaconda3\\lib\\site-packages\\IPython\\core\\interactiveshell.py\u001b[0m in \u001b[0;36mshowtraceback\u001b[1;34m(self, exc_tuple, filename, tb_offset, exception_only, running_compiled_code)\u001b[0m\n\u001b[0;32m   2043\u001b[0m                         \u001b[1;31m# in the engines. This should return a list of strings.\u001b[0m\u001b[1;33m\u001b[0m\u001b[1;33m\u001b[0m\u001b[1;33m\u001b[0m\u001b[0m\n\u001b[1;32m-> 2044\u001b[1;33m                         \u001b[0mstb\u001b[0m \u001b[1;33m=\u001b[0m \u001b[0mvalue\u001b[0m\u001b[1;33m.\u001b[0m\u001b[0m_render_traceback_\u001b[0m\u001b[1;33m(\u001b[0m\u001b[1;33m)\u001b[0m\u001b[1;33m\u001b[0m\u001b[1;33m\u001b[0m\u001b[0m\n\u001b[0m\u001b[0;32m   2045\u001b[0m                     \u001b[1;32mexcept\u001b[0m \u001b[0mException\u001b[0m\u001b[1;33m:\u001b[0m\u001b[1;33m\u001b[0m\u001b[1;33m\u001b[0m\u001b[0m\n",
      "\u001b[1;31mAttributeError\u001b[0m: 'ImportError' object has no attribute '_render_traceback_'",
      "\nDuring handling of the above exception, another exception occurred:\n",
      "\u001b[1;31mTypeError\u001b[0m                                 Traceback (most recent call last)",
      "\u001b[1;32m~\\anaconda3\\lib\\site-packages\\IPython\\core\\interactiveshell.py\u001b[0m in \u001b[0;36mrun_code\u001b[1;34m(self, code_obj, result, async_)\u001b[0m\n\u001b[0;32m   3346\u001b[0m             \u001b[1;32mif\u001b[0m \u001b[0mresult\u001b[0m \u001b[1;32mis\u001b[0m \u001b[1;32mnot\u001b[0m \u001b[1;32mNone\u001b[0m\u001b[1;33m:\u001b[0m\u001b[1;33m\u001b[0m\u001b[1;33m\u001b[0m\u001b[0m\n\u001b[0;32m   3347\u001b[0m                 \u001b[0mresult\u001b[0m\u001b[1;33m.\u001b[0m\u001b[0merror_in_exec\u001b[0m \u001b[1;33m=\u001b[0m \u001b[0msys\u001b[0m\u001b[1;33m.\u001b[0m\u001b[0mexc_info\u001b[0m\u001b[1;33m(\u001b[0m\u001b[1;33m)\u001b[0m\u001b[1;33m[\u001b[0m\u001b[1;36m1\u001b[0m\u001b[1;33m]\u001b[0m\u001b[1;33m\u001b[0m\u001b[1;33m\u001b[0m\u001b[0m\n\u001b[1;32m-> 3348\u001b[1;33m             \u001b[0mself\u001b[0m\u001b[1;33m.\u001b[0m\u001b[0mshowtraceback\u001b[0m\u001b[1;33m(\u001b[0m\u001b[0mrunning_compiled_code\u001b[0m\u001b[1;33m=\u001b[0m\u001b[1;32mTrue\u001b[0m\u001b[1;33m)\u001b[0m\u001b[1;33m\u001b[0m\u001b[1;33m\u001b[0m\u001b[0m\n\u001b[0m\u001b[0;32m   3349\u001b[0m         \u001b[1;32melse\u001b[0m\u001b[1;33m:\u001b[0m\u001b[1;33m\u001b[0m\u001b[1;33m\u001b[0m\u001b[0m\n\u001b[0;32m   3350\u001b[0m             \u001b[0moutflag\u001b[0m \u001b[1;33m=\u001b[0m \u001b[1;32mFalse\u001b[0m\u001b[1;33m\u001b[0m\u001b[1;33m\u001b[0m\u001b[0m\n",
      "\u001b[1;32m~\\anaconda3\\lib\\site-packages\\IPython\\core\\interactiveshell.py\u001b[0m in \u001b[0;36mshowtraceback\u001b[1;34m(self, exc_tuple, filename, tb_offset, exception_only, running_compiled_code)\u001b[0m\n\u001b[0;32m   2045\u001b[0m                     \u001b[1;32mexcept\u001b[0m \u001b[0mException\u001b[0m\u001b[1;33m:\u001b[0m\u001b[1;33m\u001b[0m\u001b[1;33m\u001b[0m\u001b[0m\n\u001b[0;32m   2046\u001b[0m                         stb = self.InteractiveTB.structured_traceback(etype,\n\u001b[1;32m-> 2047\u001b[1;33m                                             value, tb, tb_offset=tb_offset)\n\u001b[0m\u001b[0;32m   2048\u001b[0m \u001b[1;33m\u001b[0m\u001b[0m\n\u001b[0;32m   2049\u001b[0m                     \u001b[0mself\u001b[0m\u001b[1;33m.\u001b[0m\u001b[0m_showtraceback\u001b[0m\u001b[1;33m(\u001b[0m\u001b[0metype\u001b[0m\u001b[1;33m,\u001b[0m \u001b[0mvalue\u001b[0m\u001b[1;33m,\u001b[0m \u001b[0mstb\u001b[0m\u001b[1;33m)\u001b[0m\u001b[1;33m\u001b[0m\u001b[1;33m\u001b[0m\u001b[0m\n",
      "\u001b[1;32m~\\anaconda3\\lib\\site-packages\\IPython\\core\\ultratb.py\u001b[0m in \u001b[0;36mstructured_traceback\u001b[1;34m(self, etype, value, tb, tb_offset, number_of_lines_of_context)\u001b[0m\n\u001b[0;32m   1416\u001b[0m             \u001b[0mself\u001b[0m\u001b[1;33m.\u001b[0m\u001b[0mtb\u001b[0m \u001b[1;33m=\u001b[0m \u001b[0mtb\u001b[0m\u001b[1;33m\u001b[0m\u001b[1;33m\u001b[0m\u001b[0m\n\u001b[0;32m   1417\u001b[0m         return FormattedTB.structured_traceback(\n\u001b[1;32m-> 1418\u001b[1;33m             self, etype, value, tb, tb_offset, number_of_lines_of_context)\n\u001b[0m\u001b[0;32m   1419\u001b[0m \u001b[1;33m\u001b[0m\u001b[0m\n\u001b[0;32m   1420\u001b[0m \u001b[1;33m\u001b[0m\u001b[0m\n",
      "\u001b[1;32m~\\anaconda3\\lib\\site-packages\\IPython\\core\\ultratb.py\u001b[0m in \u001b[0;36mstructured_traceback\u001b[1;34m(self, etype, value, tb, tb_offset, number_of_lines_of_context)\u001b[0m\n\u001b[0;32m   1316\u001b[0m             \u001b[1;31m# Verbose modes need a full traceback\u001b[0m\u001b[1;33m\u001b[0m\u001b[1;33m\u001b[0m\u001b[1;33m\u001b[0m\u001b[0m\n\u001b[0;32m   1317\u001b[0m             return VerboseTB.structured_traceback(\n\u001b[1;32m-> 1318\u001b[1;33m                 \u001b[0mself\u001b[0m\u001b[1;33m,\u001b[0m \u001b[0metype\u001b[0m\u001b[1;33m,\u001b[0m \u001b[0mvalue\u001b[0m\u001b[1;33m,\u001b[0m \u001b[0mtb\u001b[0m\u001b[1;33m,\u001b[0m \u001b[0mtb_offset\u001b[0m\u001b[1;33m,\u001b[0m \u001b[0mnumber_of_lines_of_context\u001b[0m\u001b[1;33m\u001b[0m\u001b[1;33m\u001b[0m\u001b[0m\n\u001b[0m\u001b[0;32m   1319\u001b[0m             )\n\u001b[0;32m   1320\u001b[0m         \u001b[1;32melif\u001b[0m \u001b[0mmode\u001b[0m \u001b[1;33m==\u001b[0m \u001b[1;34m'Minimal'\u001b[0m\u001b[1;33m:\u001b[0m\u001b[1;33m\u001b[0m\u001b[1;33m\u001b[0m\u001b[0m\n",
      "\u001b[1;32m~\\anaconda3\\lib\\site-packages\\IPython\\core\\ultratb.py\u001b[0m in \u001b[0;36mstructured_traceback\u001b[1;34m(self, etype, evalue, etb, tb_offset, number_of_lines_of_context)\u001b[0m\n\u001b[0;32m   1184\u001b[0m         \u001b[0mexception\u001b[0m \u001b[1;33m=\u001b[0m \u001b[0mself\u001b[0m\u001b[1;33m.\u001b[0m\u001b[0mget_parts_of_chained_exception\u001b[0m\u001b[1;33m(\u001b[0m\u001b[0mevalue\u001b[0m\u001b[1;33m)\u001b[0m\u001b[1;33m\u001b[0m\u001b[1;33m\u001b[0m\u001b[0m\n\u001b[0;32m   1185\u001b[0m         \u001b[1;32mif\u001b[0m \u001b[0mexception\u001b[0m\u001b[1;33m:\u001b[0m\u001b[1;33m\u001b[0m\u001b[1;33m\u001b[0m\u001b[0m\n\u001b[1;32m-> 1186\u001b[1;33m             \u001b[0mformatted_exceptions\u001b[0m \u001b[1;33m+=\u001b[0m \u001b[0mself\u001b[0m\u001b[1;33m.\u001b[0m\u001b[0mprepare_chained_exception_message\u001b[0m\u001b[1;33m(\u001b[0m\u001b[0mevalue\u001b[0m\u001b[1;33m.\u001b[0m\u001b[0m__cause__\u001b[0m\u001b[1;33m)\u001b[0m\u001b[1;33m\u001b[0m\u001b[1;33m\u001b[0m\u001b[0m\n\u001b[0m\u001b[0;32m   1187\u001b[0m             \u001b[0metype\u001b[0m\u001b[1;33m,\u001b[0m \u001b[0mevalue\u001b[0m\u001b[1;33m,\u001b[0m \u001b[0metb\u001b[0m \u001b[1;33m=\u001b[0m \u001b[0mexception\u001b[0m\u001b[1;33m\u001b[0m\u001b[1;33m\u001b[0m\u001b[0m\n\u001b[0;32m   1188\u001b[0m         \u001b[1;32melse\u001b[0m\u001b[1;33m:\u001b[0m\u001b[1;33m\u001b[0m\u001b[1;33m\u001b[0m\u001b[0m\n",
      "\u001b[1;31mTypeError\u001b[0m: can only concatenate str (not \"list\") to str"
     ]
    }
   ],
   "source": [
    "# Imports\n",
    "import os\n",
    "import sys\n",
    "import inspect\n",
    "import numpy as np\n",
    "import tensorflow as tf\n",
    "import matplotlib.pyplot as plt\n",
    "import matplotlib as mat\n",
    "from modulos import utils\n",
    "from datetime import datetime\n",
    "from tensorflow.python.framework import ops\n",
    "from sklearn.metrics import accuracy_score\n",
    "from sklearn.metrics import precision_recall_fscore_support\n",
    "import sklearn as sk\n",
    "%matplotlib inline"
   ]
  },
  {
   "cell_type": "code",
   "execution_count": null,
   "metadata": {},
   "outputs": [],
   "source": [
    "np.__version__"
   ]
  },
  {
   "cell_type": "code",
   "execution_count": null,
   "metadata": {},
   "outputs": [],
   "source": [
    "tf.__version__"
   ]
  },
  {
   "cell_type": "code",
   "execution_count": null,
   "metadata": {},
   "outputs": [],
   "source": [
    "mat.__version__"
   ]
  },
  {
   "cell_type": "code",
   "execution_count": null,
   "metadata": {},
   "outputs": [],
   "source": [
    "sk.__version__"
   ]
  },
  {
   "cell_type": "code",
   "execution_count": null,
   "metadata": {},
   "outputs": [],
   "source": [
    "import warnings\n",
    "warnings.filterwarnings(\"ignore\")\n",
    "os.environ['TF_CPP_MIN_LOG_LEVEL'] = '3'\n",
    "ops.reset_default_graph()\n",
    "np.random.seed(123456789)"
   ]
  },
  {
   "cell_type": "code",
   "execution_count": null,
   "metadata": {},
   "outputs": [],
   "source": [
    "FLAGS = tf.flags.FLAGS\n",
    "tf.flags.DEFINE_string(\"data_dir\", \"dataset/\", \"Caminho para o diretório com dados de treino e de teste\")\n",
    "tf.flags.DEFINE_string(\"logs_dir\", \"modelo/\", \"Caminho para o diretório onde o modelo será gravado\")\n",
    "tf.flags.DEFINE_string(\"mode\", \"train\", \"mode: train (Default)/ test\")"
   ]
  },
  {
   "cell_type": "code",
   "execution_count": null,
   "metadata": {},
   "outputs": [],
   "source": [
    "# Hyperparâmetros\n",
    "BATCH_SIZE = 128\n",
    "LEARNING_RATE = 1e-3\n",
    "MAX_ITERATIONS = 1000\n",
    "REGULARIZATION = 1e-3\n",
    "IMAGE_SIZE = 48\n",
    "NUM_LABELS = 7\n",
    "VALIDATION_PERCENT = 0.1"
   ]
  },
  {
   "cell_type": "markdown",
   "metadata": {},
   "source": [
    "### Funções Auxiliares Para Construção do Modelo"
   ]
  },
  {
   "cell_type": "code",
   "execution_count": null,
   "metadata": {},
   "outputs": [],
   "source": [
    "def add_to_regularization_loss(W, b):\n",
    "    tf.add_to_collection(\"losses\", tf.nn.l2_loss(W))\n",
    "    tf.add_to_collection(\"losses\", tf.nn.l2_loss(b))"
   ]
  },
  {
   "cell_type": "code",
   "execution_count": null,
   "metadata": {},
   "outputs": [],
   "source": [
    "def weight_variable(shape, stddev=0.02, name=None):\n",
    "    initial = tf.truncated_normal(shape, stddev=stddev)\n",
    "    if name is None:\n",
    "        return tf.Variable(initial)\n",
    "    else:\n",
    "        return tf.get_variable(name, initializer=initial)"
   ]
  },
  {
   "cell_type": "code",
   "execution_count": null,
   "metadata": {},
   "outputs": [],
   "source": [
    "def bias_variable(shape, name=None):\n",
    "    initial = tf.constant(0.0, shape=shape)\n",
    "    if name is None:\n",
    "        return tf.Variable(initial)\n",
    "    else:\n",
    "        return tf.get_variable(name, initializer=initial)"
   ]
  },
  {
   "cell_type": "markdown",
   "metadata": {},
   "source": [
    "### Construção do Modelo"
   ]
  },
  {
   "cell_type": "code",
   "execution_count": null,
   "metadata": {},
   "outputs": [],
   "source": [
    "def emotionCNN(dataset):\n",
    "    \n",
    "    # Camada de Convolução 1\n",
    "    with tf.name_scope(\"conv1\") as scope:\n",
    "        tf.summary.histogram(\"W_conv1\", weights['wc1'])\n",
    "        tf.summary.histogram(\"b_conv1\", biases['bc1'])\n",
    "        conv_1 = tf.nn.conv2d(dataset, weights['wc1'], strides=[1, 1, 1, 1], padding=\"SAME\")\n",
    "        h_conv1 = tf.nn.bias_add(conv_1, biases['bc1'])\n",
    "        h_1 = tf.nn.relu(h_conv1)\n",
    "        h_pool1 = tf.nn.max_pool(h_1, ksize=[1, 2, 2, 1], strides=[1, 2, 2, 1], padding=\"SAME\")\n",
    "        add_to_regularization_loss(weights['wc1'], biases['bc1'])\n",
    "\n",
    "    # Camada de Convolução 2\n",
    "    with tf.name_scope(\"conv2\") as scope:\n",
    "        tf.summary.histogram(\"W_conv2\", weights['wc2'])\n",
    "        tf.summary.histogram(\"b_conv2\", biases['bc2'])\n",
    "        conv_2 = tf.nn.conv2d(h_pool1, weights['wc2'], strides=[1, 1, 1, 1], padding=\"SAME\")\n",
    "        h_conv2 = tf.nn.bias_add(conv_2, biases['bc2'])\n",
    "        h_2 = tf.nn.relu(h_conv2)\n",
    "        h_pool2 = tf.nn.max_pool(h_2, ksize=[1, 2, 2, 1], strides=[1, 2, 2, 1], padding=\"SAME\")\n",
    "        add_to_regularization_loss(weights['wc2'], biases['bc2'])\n",
    "\n",
    "    # Camada Totalmente Conectada 1\n",
    "    with tf.name_scope(\"fc_1\") as scope:\n",
    "        prob = 0.5\n",
    "        image_size = IMAGE_SIZE // 4\n",
    "        h_flat = tf.reshape(h_pool2, [-1, image_size * image_size * 64])\n",
    "        tf.summary.histogram(\"W_fc1\", weights['wf1'])\n",
    "        tf.summary.histogram(\"b_fc1\", biases['bf1'])\n",
    "        h_fc1 = tf.nn.relu(tf.matmul(h_flat, weights['wf1']) + biases['bf1'])\n",
    "        h_fc1_dropout = tf.nn.dropout(h_fc1, prob)\n",
    "        \n",
    "    # Camada Totalmente Conectada 2\n",
    "    with tf.name_scope(\"fc_2\") as scope:\n",
    "        tf.summary.histogram(\"W_fc2\", weights['wf2'])\n",
    "        tf.summary.histogram(\"b_fc2\", biases['bf2'])\n",
    "        pred = tf.matmul(h_fc1_dropout, weights['wf2']) + biases['bf2']\n",
    "\n",
    "    return pred"
   ]
  },
  {
   "cell_type": "code",
   "execution_count": null,
   "metadata": {},
   "outputs": [],
   "source": [
    "# Pesos e Bias do Modelo\n",
    "weights = {\n",
    "    'wc1': weight_variable([5, 5, 1, 32], name=\"W_conv1\"),\n",
    "    'wc2': weight_variable([3, 3, 32, 64],name=\"W_conv2\"),\n",
    "    'wf1': weight_variable([int((IMAGE_SIZE // 4) * (IMAGE_SIZE // 4)) * 64, 256],name=\"W_fc1\"),\n",
    "    'wf2': weight_variable([256, NUM_LABELS], name=\"W_fc2\")\n",
    "}\n",
    "\n",
    "biases = {\n",
    "    'bc1': bias_variable([32], name=\"b_conv1\"),\n",
    "    'bc2': bias_variable([64], name=\"b_conv2\"),\n",
    "    'bf1': bias_variable([256], name=\"b_fc1\"),\n",
    "    'bf2': bias_variable([NUM_LABELS], name=\"b_fc2\")\n",
    "}"
   ]
  },
  {
   "cell_type": "code",
   "execution_count": null,
   "metadata": {},
   "outputs": [],
   "source": [
    "def loss(pred, label):\n",
    "    cross_entropy_loss = tf.reduce_mean(tf.nn.softmax_cross_entropy_with_logits(logits=pred, labels=label))\n",
    "    tf.summary.scalar('Entropy', cross_entropy_loss)\n",
    "    reg_losses = tf.add_n(tf.get_collection(\"losses\"))\n",
    "    tf.summary.scalar('Reg_loss', reg_losses)\n",
    "    return cross_entropy_loss + REGULARIZATION * reg_losses"
   ]
  },
  {
   "cell_type": "code",
   "execution_count": null,
   "metadata": {},
   "outputs": [],
   "source": [
    "def train(loss, step):\n",
    "    return tf.train.AdamOptimizer(LEARNING_RATE).minimize(loss, global_step=step)"
   ]
  },
  {
   "cell_type": "code",
   "execution_count": null,
   "metadata": {},
   "outputs": [],
   "source": [
    "def get_next_batch(images, labels, step):\n",
    "    offset = (step * BATCH_SIZE) % (images.shape[0] - BATCH_SIZE)\n",
    "    batch_images = images[offset: offset + BATCH_SIZE]\n",
    "    batch_labels = labels[offset:offset + BATCH_SIZE]\n",
    "    return batch_images, batch_labels"
   ]
  },
  {
   "cell_type": "code",
   "execution_count": null,
   "metadata": {},
   "outputs": [],
   "source": [
    "# Listas para resultados de treinamento\n",
    "train_error_list = []\n",
    "train_step_list = []\n",
    "\n",
    "# Listas para resultados de validação\n",
    "valid_error_list = []\n",
    "valid_step_list = []"
   ]
  },
  {
   "cell_type": "markdown",
   "metadata": {},
   "source": [
    "### Treinamento"
   ]
  },
  {
   "cell_type": "code",
   "execution_count": null,
   "metadata": {},
   "outputs": [],
   "source": [
    "def main(argv=None):\n",
    "    \n",
    "    # Carrega os dados\n",
    "    train_images, train_labels, valid_images, valid_labels, test_images = utils.read_data(FLAGS.data_dir)\n",
    "    \n",
    "    print(\"\\nTamanho do Dataset de Treino: %s\" % train_images.shape[0])\n",
    "    print('Tamanho do Dataset de Validação: %s' % valid_images.shape[0])\n",
    "    print(\"Tamanho do Dataset de Teste: %s\" % test_images.shape[0])\n",
    "\n",
    "    global_step = tf.Variable(0, trainable=False)\n",
    "    dropout_prob = tf.placeholder(tf.float32)\n",
    "    input_dataset = tf.placeholder(tf.float32, [None, IMAGE_SIZE, IMAGE_SIZE, 1], name=\"input\")\n",
    "    input_labels = tf.placeholder(tf.float32, [None, NUM_LABELS])\n",
    "\n",
    "    pred = emotionCNN(input_dataset)\n",
    "    output_pred = tf.nn.softmax(pred, name=\"output\")\n",
    "    loss_val = loss(pred, input_labels)\n",
    "    train_op = train(loss_val, global_step)\n",
    "\n",
    "    summary_op = tf.summary.merge_all()\n",
    "    init_op = tf.global_variables_initializer()\n",
    "\n",
    "    with tf.Session() as sess:\n",
    "        sess.run(init_op)\n",
    "        summary_writer = tf.summary.FileWriter(FLAGS.logs_dir, sess.graph)\n",
    "        saver = tf.train.Saver()\n",
    "        ckpt = tf.train.get_checkpoint_state(FLAGS.logs_dir)\n",
    "        if ckpt and ckpt.model_checkpoint_path:\n",
    "            saver.restore(sess, ckpt.model_checkpoint_path)\n",
    "            print(\"Modelo Restaurado!\")\n",
    "\n",
    "        for step in range(MAX_ITERATIONS):\n",
    "            batch_image, batch_label = get_next_batch(train_images, train_labels, step)\n",
    "            feed_dict = {input_dataset: batch_image, input_labels: batch_label}\n",
    "\n",
    "            sess.run(train_op, feed_dict=feed_dict)\n",
    "            if step % 10 == 0:\n",
    "                train_loss, summary_str = sess.run([loss_val, summary_op], feed_dict=feed_dict)\n",
    "                summary_writer.add_summary(summary_str, global_step=step)\n",
    "                train_error_list.append(train_loss)\n",
    "                train_step_list.append(step)\n",
    "                print(\"Taxa de Erro no Treinamento: %f\" % train_loss)\n",
    "\n",
    "            if step % 100 == 0:\n",
    "                valid_loss = sess.run(loss_val, feed_dict={input_dataset: valid_images, input_labels: valid_labels})\n",
    "                valid_error_list.append(valid_loss)\n",
    "                valid_step_list.append(step)\n",
    "                print(\"%s Taxa de Erro na Validação: %f\" % (datetime.now(), valid_loss))\n",
    "                saver.save(sess, FLAGS.logs_dir + 'model.ckpt', global_step=step)\n",
    "        \n",
    "        # Plot do erro durante o treinamento\n",
    "        plt.plot(train_step_list, train_error_list, 'r--', label='Erro no Treinamento Por Iteração', linewidth=4)\n",
    "        plt.title('Erro no Treinamento Por Iteração')\n",
    "        plt.xlabel('Iteração')\n",
    "        plt.ylabel('Erro no Treinamento')\n",
    "        plt.legend(loc='upper right')\n",
    "        plt.show()\n",
    "\n",
    "        # Plot do erro durante a validação\n",
    "        plt.plot(valid_step_list, valid_error_list, 'r--', label='Erro na Validação Por Iteração', linewidth=4)\n",
    "        plt.title('Erro na Validação Por Iteração')\n",
    "        plt.xlabel('Iteração')\n",
    "        plt.ylabel('Erro na Validação')\n",
    "        plt.legend(loc='upper right')\n",
    "        plt.show()  \n",
    "\n",
    "print(train_error_list) \n",
    "print(valid_error_list) "
   ]
  },
  {
   "cell_type": "code",
   "execution_count": null,
   "metadata": {},
   "outputs": [],
   "source": [
    "if __name__ == \"__main__\":\n",
    "    tf.app.run()\n",
    "    print(\"Treinanento concluído\")"
   ]
  },
  {
   "cell_type": "markdown",
   "metadata": {},
   "source": [
    "Para adquirir conhecimento técnico sólido e especializado em Deep Learning, Visão Computacional, Processamento de Linguagem Natural e outros temas relacionados à Inteligência Artificial, confira nosso programa completo: <a href=\"https://www.datascienceacademy.com.br/pages/formacao-inteligencia-artificial\">Formação Inteligência Artificial</a>."
   ]
  },
  {
   "cell_type": "markdown",
   "metadata": {},
   "source": [
    "# Fim"
   ]
  },
  {
   "cell_type": "markdown",
   "metadata": {},
   "source": [
    "### Obrigado - Data Science Academy - <a href=\"http://facebook.com/dsacademybr\">facebook.com/dsacademybr</a>"
   ]
  }
 ],
 "metadata": {
  "kernelspec": {
   "display_name": "Python 3",
   "language": "python",
   "name": "python3"
  },
  "language_info": {
   "codemirror_mode": {
    "name": "ipython",
    "version": 3
   },
   "file_extension": ".py",
   "mimetype": "text/x-python",
   "name": "python",
   "nbconvert_exporter": "python",
   "pygments_lexer": "ipython3",
   "version": "3.7.6"
  }
 },
 "nbformat": 4,
 "nbformat_minor": 2
}
